import { describe, it, expect, vi, beforeEach } from 'vitest'
import { FindPaymentByIdUseCase } from '.'
import { CustomError } from '../../custom-error'

describe('FindPaymentByIdUseCase', () => {
    let findPaymentByIdRepository: any
    let useCase: FindPaymentByIdUseCase
    const mockPayment = {
        id: 1,
        orderId: 1,
        paymentStatus: 'PAID',
        paidAt: new Date(),
    }

    beforeEach(() => {
        findPaymentByIdRepository = {
            execute: vi.fn(),
            finish: vi.fn().mockResolvedValue(undefined),
        }
        useCase = new FindPaymentByIdUseCase(findPaymentByIdRepository)
    })

    it('should return payment if found', async () => {
        findPaymentByIdRepository.execute.mockResolvedValue(mockPayment)
        const result = await useCase.execute({ id: 1 })
        expect(findPaymentByIdRepository.execute).toHaveBeenCalledWith(1)
        expect(result.success).toBe(true)
        expect(result.result).toEqual(mockPayment)
    })

    it('should return error if payment not found', async () => {
        findPaymentByIdRepository.execute.mockResolvedValue(null)
        const result = await useCase.execute({ id: 2 })
        expect(result.success).toBe(false)
        expect(result.result).toBeNull()
        expect(result.error).toBeInstanceOf(CustomError)
        expect(result.error?.message).toBe('Payment not found.')
        expect(result.error?.code).toBe(404)
    })

    it('should return error if repository throws', async () => {
        findPaymentByIdRepository.execute.mockRejectedValue(new Error('DB error'))
        const result = await useCase.execute({ id: 1 })
        expect(result.success).toBe(false)
        expect(result.result).toBeNull()
        expect(result.error).toBeUndefined()
    })

    it('should call finish on onFinish', async () => {
        await useCase.onFinish()
        expect(findPaymentByIdRepository.finish).toHaveBeenCalled()
    })
})
